<?xml version="1.0"?>
<robot xmlns:xacro="http://www.ros.org/wiki/xacro" >

<xacro:include filename = "inertial_macros.xacro" />


    <material name="white">
        <color rgba="1 1 1 1" />
    </material>

    <material name="orange">
        <color rgba="1 0.3 0.1 1"/>
    </material>

    <material name="blue">
        <color rgba="0.2 0.2 1 1"/>
    </material>

    <material name="red">
        <color rgba="1 0 0 1"/>
    </material>

    <material name = "black">
        <color rgba = "0 0 0 1" />
    </material>

    <material name="yellow" >
        <color rgba="1.0 1.0 0.0784313725490196 1.0" />
    </material>

    <!-- BASE LINK -->

    <link name="base_link"></link>

    <link name = "base_footprint"></link>

    <joint name = "base_footprint_joint" type = "fixed">
        <parent link = "base_link" />
        <child link = "base_footprint" />
        <origin xyz = "0 0 0" rpy= "0 0 0" />
    </joint>


    <!-- CHASSIS LINK -->

    <joint name="chassis_joint" type="fixed">
        <parent link="base_link"/>
        <child link="chassis"/>
        <origin xyz="-0.1 0 0"/>
    </joint>

    <link name="chassis">
        <visual>
            <origin xyz="0.15 0 0.075"/>
            <geometry>
                <box size="0.3 0.3 0.15"/>
            </geometry>
            <material name="black"/>
        </visual>

        <collision>
            <origin xyz="0.15 0 0.075"/>
            <geometry>
                <box size="0.3 0.3 0.15"/>
            </geometry>
        </collision>

        <xacro:inertial_box mass = "0.5" x = "0.3" y = "0.3" z = "0.15" >
            <origin xyz = "0 0 0" rpy= "0 0 0" />
        </xacro:inertial_box>
    
    </link>

    <gazebo reference = "chassis">
        <material>Gazebo/Black</material>
    </gazebo>

    <joint name = "left_wheel_joint" type = "continuous">
        <parent link = "chassis" />
        <child link = "left_wheel" />
        <origin xyz = "0 0.17 0" rpy = "1.57 0 0" />
        <axis xyz = "0 0 -1" />
    </joint>

    <link name = 'left_wheel'>
        <visual>
            <geometry>
                <cylinder radius = "0.05" length = "0.04" />
            </geometry>
            <material name = "white" />
        </visual>

        <collision>
            <geometry>
                <cylinder radius = "0.05" length = "0.04" />
            </geometry>
        </collision>

        <xacro:inertial_cylinder mass = "0.1" radius = "0.05" length = "0.04">
            <origin xyz = "0 0 0" rpy = "0 0 0" />
        </xacro:inertial_cylinder>
    </link>

    <gazebo reference = "left_wheel">
        <material>Gazebo/White</material>
    </gazebo>

    <joint name = "right_wheel_joint" type = "continuous">
        <parent link = "chassis" />
        <child link = "right_wheel" />
        <origin xyz = "0 -0.17 0" rpy = "1.57 0 0" />
        <axis xyz = "0 0 -1" />
    </joint>

    <link name = 'right_wheel'>
        <visual>
            <geometry>
                <cylinder radius = "0.05" length = "0.04" />
            </geometry>
            <material name = "white" />
        </visual>

        <collision>
            <geometry>
                <cylinder radius = "0.05" length = "0.04" />
            </geometry>
        </collision>

        <xacro:inertial_cylinder mass = "0.1" radius = "0.05" length = "0.04">
            <origin xyz = "0 0 0" rpy = "0 0 0" />
        </xacro:inertial_cylinder>
    </link>

    <gazebo reference = "right_wheel">
        <material>Gazebo/White</material>
    </gazebo>

    <joint name = "caster_wheel_joint" type = "fixed">
        <parent link = "chassis" />
        <child link = "caster_wheel" />
        <origin xyz = "0.24 0 0" rpy = "0 0 0" />
    </joint>
    
    <link name = "caster_wheel">
        <visual>
            <geometry>
                <sphere radius = "0.05" />
            </geometry>
            <material name = "red" />
        </visual>

        <collision>
            <geometry>
                <sphere radius = "0.05" />
            </geometry>
        </collision>

        <xacro:inertial_sphere mass = "0.1" radius = "0.05">
            <origin xyz = "0 0 0" rpy = "0 0 0" />
        </xacro:inertial_sphere>
    </link>

    <gazebo reference = "caster_wheel">
        <material>Gazebo/Red</material>
        <mu1 value = "0.003" />
        <mu2 value = "0.003" />
    </gazebo>

    <joint name="left_hand_joint" type="fixed">
        <parent link="chassis"/>
        <child link="left_hand"/>
        <origin xyz="-0.03 0.15 0.15" rpy = "-${pi/6} ${pi/6} 0"/>
    </joint>

    <link name="left_hand">
        <visual>
            <geometry>
                <box size="0.18 0.008 0.08"/>
            </geometry>
            <material name="blue"/>
        </visual>

        <collision>
            <geometry>
                <box size="0.18 0.008 0.08"/>
            </geometry>
        </collision>

        <xacro:inertial_box mass = "0.1" x= "0.18" y = "0.008" z = "0.08">
            <origin xyz = "0 0 0" rpy = "0 0 0" />
        </xacro:inertial_box>
    </link>

    <gazebo reference = "left_hand">
        <material>Gazebo/Blue</material>
    </gazebo>


    <joint name="right_hand_joint" type="fixed">
        <parent link="chassis"/>
        <child link="right_hand"/>
        <origin xyz="-0.03 -0.15 0.15" rpy = "${pi/6} ${pi/6} 0"/>
    </joint>

    <link name="right_hand">
        <visual>
            <geometry>
                <box size="0.18 0.008 0.08"/>
            </geometry>
            <material name="blue"/>
        </visual>

        <collision>
            <geometry>
                <box size="0.18 0.008 0.08"/>
            </geometry>
        </collision>
        
        <xacro:inertial_box mass = "0.1" x= "0.18" y = "0.008" z = "0.08">
            <origin xyz = "0 0 0" rpy = "0 0 0" />
        </xacro:inertial_box>
    </link>

    <gazebo reference = "right_hand">
        <material>Gazebo/Blue</material>
    </gazebo>

    <joint name = "left_eye_joint" type = "fixed">
        <parent link = "chassis" />
        <child link = "left_eye" />
        <origin xyz = "0.30 -0.05 0.075" />
    </joint>

    <link name = "left_eye">
        <visual>
            <geometry>
                <sphere radius = "0.01" />
            </geometry>
            <material name = "red" />
        </visual>
    </link>

    <gazebo reference = "left_eye">
        <material>Gazebo/Red</material>
    </gazebo>

    <joint name = "right_eye_joint" type = "fixed">
        <parent link = "chassis" />
        <child link = "right_eye" />
        <origin xyz = "0.30 0.05 0.075" />
    </joint>

    <link name = "right_eye">
        <visual>
            <geometry>
                <sphere radius = "0.01" />
            </geometry>
            <material name = "red" />
        </visual>
    </link>

    <gazebo reference = "right_eye">
        <material>Gazebo/Red</material>
    </gazebo>
        
    <joint name = "left_eyebrow_joint" type = "fixed">
        <parent link = "chassis" />
        <child link = "left_eyebrow" />
        <origin xyz = "0.295 -0.06 0.12" rpy = "${pi/3} 0 0"/>
    </joint>

    <link name = "left_eyebrow">
        <visual>
            <geometry>
                <cylinder radius = "0.01" length = "0.06" />
            </geometry>
            <material name = "yellow" />
        </visual>
    </link>

    <gazebo reference = "left_eyebrow">
        <material>Gazebo/Yellow</material>
    </gazebo>

    <joint name = "right_eyebrow_joint" type = "fixed">
        <parent link = "chassis" />
        <child link = "right_eyebrow" />
        <origin xyz = "0.295 0.06 0.12" rpy = "-${pi/3} 0 0"/>
    </joint>

    <link name = "right_eyebrow">
        <visual>
            <geometry>
                <cylinder radius = "0.01" length = "0.06" />
            </geometry>
            <material name = "yellow" />
        </visual>
    </link>

    <gazebo reference = "right_eyebrow">
        <material>Gazebo/Yellow</material>
    </gazebo>

</robot>